<?xml version="1.0" encoding="UTF-8"?>
<!-- Generated by org.testng.reporters.JUnitReportReporter -->
<testsuite hostname="Prash_Laptop" failures="1" tests="4" name="Login.LoginTest" time="24.148" errors="0" timestamp="2025-04-04T20:33:13 IST" skipped="3">
  <testcase classname="Login.LoginTest" name="LoginTest" time="6.474">
    <skipped/>
  </testcase> <!-- LoginTest -->
  <testcase classname="Login.LoginTest" name="LoginTest" time="5.648">
    <skipped/>
  </testcase> <!-- LoginTest -->
  <testcase classname="Login.LoginTest" name="LoginTest" time="5.937">
    <failure message="The following asserts failed:
	Validation is failed expected [http://49.249.28.218:8098/dashboar] but found [http://49.249.28.218:8098/dashboard]" type="java.lang.AssertionError">
      <![CDATA[java.lang.AssertionError: The following asserts failed:
Validation is failed expected [http://49.249.28.218:8098/dashboar] but found [http://49.249.28.218:8098/dashboard]
at org.testng.asserts.SoftAssert.assertAll(SoftAssert.java:46)
at org.testng.asserts.SoftAssert.assertAll(SoftAssert.java:30)
at Login.LoginTest.LoginTest(LoginTest.java:86)
at java.base/jdk.internal.reflect.DirectMethodHandleAccessor.invoke(DirectMethodHandleAccessor.java:103)
at java.base/java.lang.reflect.Method.invoke(Method.java:580)
at org.testng.internal.invokers.MethodInvocationHelper.invokeMethod(MethodInvocationHelper.java:141)
at org.testng.internal.invokers.TestInvoker.invokeMethod(TestInvoker.java:686)
at org.testng.internal.invokers.TestInvoker.retryFailed(TestInvoker.java:269)
at org.testng.internal.invokers.MethodRunner.runInSequence(MethodRunner.java:76)
at org.testng.internal.invokers.TestInvoker$MethodInvocationAgent.invoke(TestInvoker.java:992)
at org.testng.internal.invokers.TestInvoker.invokeTestMethods(TestInvoker.java:203)
at org.testng.internal.invokers.TestMethodWorker.invokeTestMethods(TestMethodWorker.java:154)
at org.testng.internal.invokers.TestMethodWorker.run(TestMethodWorker.java:134)
at java.base/java.util.ArrayList.forEach(ArrayList.java:1596)
at org.testng.TestRunner.privateRun(TestRunner.java:739)
at org.testng.TestRunner.run(TestRunner.java:614)
at org.testng.SuiteRunner.runTest(SuiteRunner.java:421)
at org.testng.SuiteRunner.runSequentially(SuiteRunner.java:413)
at org.testng.SuiteRunner.privateRun(SuiteRunner.java:373)
at org.testng.SuiteRunner.run(SuiteRunner.java:312)
at org.testng.SuiteRunnerWorker.runSuite(SuiteRunnerWorker.java:52)
at org.testng.SuiteRunnerWorker.run(SuiteRunnerWorker.java:95)
at org.testng.TestNG.runSuitesSequentially(TestNG.java:1274)
at org.testng.TestNG.runSuitesLocally(TestNG.java:1208)
at org.testng.TestNG.runSuites(TestNG.java:1112)
at org.testng.TestNG.run(TestNG.java:1079)
at org.testng.remote.AbstractRemoteTestNG.run(AbstractRemoteTestNG.java:115)
at org.testng.remote.RemoteTestNG.initAndRun(RemoteTestNG.java:293)
at org.testng.remote.RemoteTestNG.main(RemoteTestNG.java:91)
]]>
    </failure>
  </testcase> <!-- LoginTest -->
  <testcase classname="Login.LoginTest" name="LoginTest" time="6.089">
    <skipped/>
  </testcase> <!-- LoginTest -->
  <system-out>
    <![CDATA[Campaign Rotherham55 added successfully
Campaign Rotherham392 added successfully
Contact Nandini209 added Successfully
Product Mobile738 Successfully added]]>
  </system-out>
</testsuite> <!-- Login.LoginTest -->
